<?xml version="1.0" ?>
<sdf version="1.6">
	<model name="ExoJoints">
		<link name="upperArm">
			<self_collide>false</self_collide>
			<pose frame="">-3.3562522522442266e-08 -0.16398020098005578 0.8533698802739308 0.0 -0.0 0.0</pose>
			<inertial>
				<pose frame="">0.0 0.0 0.0 0 0 0</pose>
				<mass>0.03536431430099496</mass>
				<inertia>
					<ixx>0.02682447387896885</ixx>
					<ixy>-1.9541071529793899e-10</ixy>
					<ixz>1.0201703000145558e-11</ixz>
					<iyy>0.025873533617720355</iyy>
					<iyz>0.0049487323574652535</iyz>
					<izz>0.000976730459058234</izz>
				</inertia>
			</inertial>
<!--			<collision name="upperArm_collision">-->
<!--				<geometry>-->
<!--					<mesh>-->
<!--						<uri>model://ExoJoints/meshes/CAD/upperArm.stl</uri>-->
<!--						<scale>0.001 0.001 0.001</scale>-->
<!--					</mesh>-->
<!--				</geometry>-->
<!--			</collision>-->
			<visual name="upperArm_visual">
				<geometry>
					<mesh>
						<uri>model://ExoJoints/meshes/CAD/upperArm.stl</uri>
						<scale>0.001 0.001 0.001</scale>
					</mesh>
				</geometry>
			</visual>
		</link>
		<link name="lowerArm">
			<self_collide>false</self_collide>
			<pose frame="">-7.634278855779988e-06 -0.16398306147892494 0.5875262784186934 0.0 -0.0 0.0</pose>
			<inertial>
				<pose frame="">0.0 0.0 0.0 0 0 0</pose>
				<mass>0.0390118006951114</mass>
				<inertia>
					<ixx>0.014632520798684736</ixx>
					<ixy>-4.902873383362261e-08</ixy>
					<ixz>1.6427794443458766e-09</ixz>
					<iyy>0.01358345867684319</iyy>
					<iyz>0.003758566893961893</iyz>
					<izz>0.0010955000169609532</izz>
				</inertia>
			</inertial>
<!--			<collision name="lowerArm_collision">-->
<!--				<geometry>-->
<!--					<mesh>-->
<!--						<uri>model://ExoJoints/meshes/CAD/lowerArm.stl</uri>-->
<!--						<scale>0.001 0.001 0.001</scale>-->
<!--					</mesh>-->
<!--				</geometry>-->
<!--			</collision>-->
			<visual name="lowerArm_visual">
				<geometry>
					<mesh>
						<uri>model://ExoJoints/meshes/CAD/lowerArm.stl</uri>
						<scale>0.001 0.001 0.001</scale>
					</mesh>
				</geometry>
			</visual>
		</link>
		<link name="shoulder">
			<self_collide>false</self_collide>
			<pose frame="">1.316289929129686e-07 -0.1639802475924226 1.0812798666063754 0.0 -0.0 0.0</pose>
			<inertial>
				<pose frame="">0.0 0.0 0.0 0 0 0</pose>
				<mass>0.01630377495379141</mass>
				<inertia>
					<ixx>0.019516873558131056</ixx>
					<ixy>3.414451968386523e-10</ixy>
					<ixz>-2.2937835697955935e-11</ixz>
					<iyy>0.019078455358144043</iyy>
					<iyz>0.002890798511049296</iyz>
					<izz>0.0004650260272225621</izz>
				</inertia>
			</inertial>
<!--			<collision name="shoulder_collision">-->
<!--				<geometry>-->
<!--					<mesh>-->
<!--						<uri>model://ExoSuitWithJoints/meshes/CAD/shoulder.stl</uri>-->
<!--						<scale>0.001 0.001 0.001</scale>-->
<!--					</mesh>-->
<!--				</geometry>-->
<!--			</collision>-->
			<visual name="shoulder_visual">
				<geometry>
					<mesh>
						<uri>model://ExoJoints/meshes/CAD/shoulder.stl</uri>
						<scale>0.001 0.001 0.001</scale>
					</mesh>
				</geometry>
			</visual>
		</link>
<!--		<joint name="offset" type="fixed">-->
<!--			<parent>world</parent>-->
<!--			<child>shoulder</child>-->
<!--		</joint>-->
		<joint name="shoulder_joint" type="revolute">
			<parent>shoulder</parent>
			<child>upperArm</child>
			<pose frame="">3.3562522522442266e-08 2.4291284717037343e-09 0.20314385644926333 0 0 0</pose>
			<axis>
				<xyz>0.0 1.0 0.0</xyz>
<!--				<limit>-->
<!--					<lower>0.0</lower>-->
<!--					<upper>0.0</upper>-->
<!--				</limit>-->
				<use_parent_model_frame>0</use_parent_model_frame>
			</axis>
		</joint>
		<joint name="elbow_joint" type="revolute">
			<parent>upperArm</parent>
			<child>lowerArm</child>
			<pose frame="">7.634278855779988e-06 2.862927997639986e-06 0.1819874583044738 0 0 0</pose>
			<axis>
				<xyz>2.064988378536746e-17 -1.0 -7.16436763573328e-33</xyz>
<!--				<limit>-->
<!--					<lower>0.0</lower>-->
<!--					<upper>0.0</upper>-->
<!--				</limit>-->
				<use_parent_model_frame>0</use_parent_model_frame>
			</axis>
		</joint>
		<plugin filename="libcardsflow_gazebo_plugin.so" name="cardsflow_gazebo_plugin"/>
	</model>
</sdf>
