<?xml version="1.0" ?>
<sdf version="1.5">
	<model name="myoarm_small">
		<muscles>model://myoarm_small/muscles.osim</muscles>
		<link name="table">
			<pose>0.0 0.0 0.0 1.5707963705062866 -0.0 0.0</pose>
			<inertial>
				<mass>10.0</mass>
				<pose>0.0 0.0 0.0 -1.5707963705062866 -0.0 0.0</pose>
				<inertia>
					<ixx>1.0</ixx>
					<ixy>0.0</ixy>
					<ixz>0.0</ixz>
					<iyy>1.0</iyy>
					<iyz>0.0</iyz>
					<izz>1.0</izz>
				</inertia>
			</inertial>
			<visual name="VIS_table">
				<pose>0.0 0.498616099357605 0.017666349187493324 -1.5707963705062866 -0.0 0.0</pose>
				<pose>0.0 0.0 0.0 -1.5707963705062866 -0.0 0.0</pose>
				<geometry>
					<mesh>
						<uri>model://myoarm_small/meshes/visual/VIS_table.dae</uri>
						<scale>1.0 1.0 1.0</scale>
					</mesh>
				</geometry>
			</visual>
		</link>
		<link name="base">
			<pose>0.0 -5.66975081794e-06 0.889999985695 1.5707963705062866 -0.0 0.0</pose>
			<inertial>
				<mass>10000.0</mass>
				<pose>0.0 -0.8899999856948853 -5.630847226711921e-06 -1.5707963705062866 -0.0 0.0</pose>
				<inertia>
					<ixx>1.0</ixx>
					<ixy>0.0</ixy>
					<ixz>0.0</ixz>
					<iyy>1.0</iyy>
					<iyz>0.0</iyz>
					<izz>1.0</izz>
				</inertia>
			</inertial>
			<visual name="VIS_base">
				<pose>0.0 0.10937470197677612 0.0027973027899861336 -6.245005191142863e-14 -0.0 0.0</pose>
				<geometry>
					<mesh>
						<uri>model://myoarm_small/meshes/visual/VIS_base.dae</uri>
						<scale>0.0009999999310821295 0.0009999999310821295 0.0009999999310821295</scale>
					</mesh>
				</geometry>
			</visual>
			<visual name="VIS_COL_base_1">
				<pose>0.0 0.10937470197677612 0.0027973027899861336 -6.245005191142863e-14 -0.0 0.0</pose>
				<pose>0.0 -0.8899999856948853 -5.630847226711921e-06 -1.5707963705062866 -0.0 0.0</pose>
				<geometry>
					<mesh>
						<uri>model://myoarm_small/meshes/visual/VIS_COL_base_1.dae</uri>
						<scale>0.0009999999310821295 0.0009999999310821295 0.0009999999310821295</scale>
					</mesh>
				</geometry>
			</visual>
		</link>
		<link name="arm">
			<pose>0.0 -0.00200569104584 1.37499999991 1.5707963705062866 -0.0 0.0</pose>
			<inertial>
				<mass>1.0</mass>
				<pose>0.0 -1.377000093460083 -8.67983908392489e-06 -1.5707963705062866 -0.0 0.0</pose>
				<inertia>
					<ixx>1.0</ixx>
					<ixy>0.0</ixy>
					<ixz>0.0</ixz>
					<iyy>1.0</iyy>
					<iyz>0.0</iyz>
					<izz>1.0</izz>
				</inertia>
			</inertial>
			<visual name="VIS_arm">
				<pose>0.000904510379768908 0.15434670448303223 0.00041864102240651846 -1.189777720789209e-10 -0.0 0.0</pose>
				<pose>0.0 -1.377000093460083 -8.67983908392489e-06 -1.5707963705062866 -0.0 0.0</pose>
				<geometry>
					<mesh>
						<uri>model://myoarm_small/meshes/visual/VIS_arm.dae</uri>
						<scale>0.0009999999310821295 0.0009999998146668077 0.0009999999310821295</scale>
					</mesh>
				</geometry>
			</visual>
		</link>
		<joint name="table" type="fixed">
			<parent>world</parent>
			<child>table</child>
			<axis>
				<xyz>1.0 0.0 0.0</xyz>
				<use_parent_model_frame>true</use_parent_model_frame>
				<limit/>
			</axis>
		</joint>
		<joint name="base" type="fixed">
			<parent>table</parent>
			<child>base</child>
			<axis>
				<xyz>1.0 0.0 0.0</xyz>
				<use_parent_model_frame>true</use_parent_model_frame>
				<limit/>
			</axis>
		</joint>
		<joint name="arm" type="revolute">
			<parent>base</parent>
			<child>arm</child>
			<axis>
				<xyz>1.0 0.0 0.0</xyz>
				<use_parent_model_frame>true</use_parent_model_frame>
				<limit>
					<lower>-1</lower>
					<upper>1</upper>
				</limit>
			</axis>
		</joint>
		<plugin filename="libgazebo_ros_muscle_interface.so" name="muscle_interface_plugin"/>
	</model>
</sdf>
