<?xml version='1.0'?>
<sdf version='1.6'>
  <model name='ExoWtihSkeletonNoJoints'>
    <model name='ExoSuitNoJoints'>
      <link name='upperArm'>
        <self_collide>0</self_collide>
        <pose frame=''>-0 -0.165701 0.853429 0 -0 0</pose>
        <inertial>
          <pose frame=''>0 0 0 0 -0 0</pose>
          <mass>0.035365</mass>
          <inertia>
            <ixx>0.0268487</ixx>
            <ixy>-1.31877e-10</ixy>
            <ixz>5.0011e-05</ixz>
            <iyy>0.0258777</iyy>
            <iyz>6.78369e-10</iyz>
            <izz>0.000996808</izz>
          </inertia>
        </inertial>
        <visual name='upperArm_visual'>
          <geometry>
            <mesh>
              <uri>model://ExoSuitNoJoints/meshes/CAD/upperArm.stl</uri>
              <scale>0.001 0.001 0.001</scale>
            </mesh>
          </geometry>
        </visual>
      </link>
      <link name='lowerArm'>
        <self_collide>0</self_collide>
        <pose frame=''>-1e-06 -0.196437 0.58865 0 -0 0</pose>
        <inertial>
          <pose frame=''>0 0 0 0 -0 0</pose>
          <mass>0.0390282</mass>
          <inertia>
            <ixx>0.0151468</ixx>
            <ixy>-4.3037e-09</ixy>
            <ixz>4.49526e-05</ixz>
            <iyy>0.013636</iyy>
            <iyz>1.19603e-08</iyz>
            <izz>0.0015572</izz>
          </inertia>
        </inertial>
        <visual name='lowerArm_visual'>
          <geometry>
            <mesh>
              <uri>model://ExoSuitNoJoints/meshes/CAD/lowerArm.stl</uri>
              <scale>0.001 0.001 0.001</scale>
            </mesh>
          </geometry>
        </visual>
      </link>
      <link name='shoulder'>
        <self_collide>0</self_collide>
        <pose frame=''>-1e-06 -0.163976 1.08128 0 -0 0</pose>
        <inertial>
          <pose frame=''>0 0 0 0 -0 0</pose>
          <mass>0.0163027</mass>
          <inertia>
            <ixx>0.0195156</ixx>
            <ixy>-1.99665e-09</ixy>
            <ixz>2.89054e-05</ixz>
            <iyy>0.0190772</iyy>
            <iyz>1.37222e-08</iyz>
            <izz>0.000464974</izz>
          </inertia>
        </inertial>
        <visual name='shoulder_visual'>
          <geometry>
            <mesh>
              <uri>model://ExoSuitNoJoints/meshes/CAD/shoulder.stl</uri>
              <scale>0.001 0.001 0.001</scale>
            </mesh>
          </geometry>
        </visual>
      </link>
      <joint name='offset' type='fixed'>
        <parent>world</parent>
        <child>shoulder</child>
      </joint>
      <plugin name='muscle_interface_plugin' filename='libgazebo_ros_muscle_interface.so'/>
      <muscles>model://ExoSuitNoJoints/muscles.osim</muscles>
      <pose frame=''>-0.007648 -0.001248 -0.100006 0 -0 0</pose>
    </model>
    <model name='arm26'>
      <muscles>model://arm26/muscles.osim</muscles>
      <link name='base'>
        <pose frame=''>0 0 0.8 1.5708 -0 0</pose>
        <inertial>
          <mass>0.0001</mass>
          <pose frame=''>0 0 0 0 -0 0</pose>
          <inertia>
            <ixx>0</ixx>
            <ixy>0</ixy>
            <ixz>0</ixz>
            <iyy>0</iyy>
            <iyz>0</iyz>
            <izz>0</izz>
          </inertia>
        </inertial>
        <visual name='ground_ribs'>
          <pose frame=''>-0 0 -0 0 -0 0</pose>
          <geometry>
            <mesh>
              <uri>model://arm26/meshes/visuals/ground_ribs.dae</uri>
              <scale>1 1 1</scale>
            </mesh>
          </geometry>
        </visual>
        <visual name='ground_spine'>
          <pose frame=''>-0 0 -0 0 -0 0</pose>
          <geometry>
            <mesh>
              <uri>model://arm26/meshes/visuals/ground_spine.dae</uri>
              <scale>1 1 1</scale>
            </mesh>
          </geometry>
        </visual>
        <visual name='ground_skull'>
          <pose frame=''>-0 0 -0 0 -0 0</pose>
          <geometry>
            <mesh>
              <uri>model://arm26/meshes/visuals/ground_skull.dae</uri>
              <scale>1 1 1</scale>
            </mesh>
          </geometry>
        </visual>
        <visual name='ground_jaw'>
          <pose frame=''>-0 0 -0 0 -0 0</pose>
          <geometry>
            <mesh>
              <uri>model://arm26/meshes/visuals/ground_jaw.dae</uri>
              <scale>1 1 1</scale>
            </mesh>
          </geometry>
        </visual>
        <visual name='ground_r_clavicle'>
          <pose frame=''>-0 0 -0 0 -0 0</pose>
          <geometry>
            <mesh>
              <uri>model://arm26/meshes/visuals/ground_r_clavicle.dae</uri>
              <scale>1 1 1</scale>
            </mesh>
          </geometry>
        </visual>
        <visual name='ground_r_scapula'>
          <pose frame=''>-0 0 -0 0 -0 0</pose>
          <geometry>
            <mesh>
              <uri>model://arm26/meshes/visuals/ground_r_scapula.dae</uri>
              <scale>1 1 1</scale>
            </mesh>
          </geometry>
        </visual>
        <self_collide>0</self_collide>
      </link>
      <link name='r_humerus'>
        <pose frame=''>-0.017545 -0.17 0.793 1.5708 -0 0</pose>
        <inertial>
          <mass>1.86457</mass>
          <pose frame=''>0 0 0 0 -0 0</pose>
          <inertia>
            <ixx>0.01481</ixx>
            <ixy>0</ixy>
            <ixz>0</ixz>
            <iyy>0.004551</iyy>
            <iyz>0</iyz>
            <izz>0.013193</izz>
          </inertia>
        </inertial>
        <visual name='arm_r_humerus'>
          <pose frame=''>-0 0 -0 0 -0 0</pose>
          <geometry>
            <mesh>
              <uri>model://arm26/meshes/visuals/arm_r_humerus.dae</uri>
              <scale>1 1 1</scale>
            </mesh>
          </geometry>
        </visual>
        <self_collide>0</self_collide>
      </link>
      <link name='r_ulna_radius_hand'>
        <pose frame=''>-0.011445 -0.1577 0.5026 1.5708 -0 0</pose>
        <inertial>
          <mass>1.53432</mass>
          <pose frame=''>0 0 0 0 -0 0</pose>
          <inertia>
            <ixx>0.019281</ixx>
            <ixy>0</ixy>
            <ixz>0</ixz>
            <iyy>0.001571</iyy>
            <iyz>0</iyz>
            <izz>0.020062</izz>
          </inertia>
        </inertial>
        <visual name='arm_r_ulna'>
          <pose frame=''>-0 0 -0 0 -0 0</pose>
          <geometry>
            <mesh>
              <uri>model://arm26/meshes/visuals/arm_r_ulna.dae</uri>
              <scale>1 1 1</scale>
            </mesh>
          </geometry>
        </visual>
        <visual name='arm_r_radius'>
          <pose frame=''>-0 0 -0 0 -0 0</pose>
          <geometry>
            <mesh>
              <uri>model://arm26/meshes/visuals/arm_r_radius.dae</uri>
              <scale>1 1 1</scale>
            </mesh>
          </geometry>
        </visual>
        <visual name='arm_r_lunate'>
          <pose frame=''>-0 0 -0 0 -0 0</pose>
          <geometry>
            <mesh>
              <uri>model://arm26/meshes/visuals/arm_r_lunate.dae</uri>
              <scale>1 1 1</scale>
            </mesh>
          </geometry>
        </visual>
        <visual name='arm_r_scaphoid'>
          <pose frame=''>-0 0 -0 0 -0 0</pose>
          <geometry>
            <mesh>
              <uri>model://arm26/meshes/visuals/arm_r_scaphoid.dae</uri>
              <scale>1 1 1</scale>
            </mesh>
          </geometry>
        </visual>
        <visual name='arm_r_pisiform'>
          <pose frame=''>-0 0 -0 0 -0 0</pose>
          <geometry>
            <mesh>
              <uri>model://arm26/meshes/visuals/arm_r_pisiform.dae</uri>
              <scale>1 1 1</scale>
            </mesh>
          </geometry>
        </visual>
        <visual name='arm_r_triquetrum'>
          <pose frame=''>-0 0 -0 0 -0 0</pose>
          <geometry>
            <mesh>
              <uri>model://arm26/meshes/visuals/arm_r_triquetrum.dae</uri>
              <scale>1 1 1</scale>
            </mesh>
          </geometry>
        </visual>
        <visual name='arm_r_capitate'>
          <pose frame=''>-0 0 -0 0 -0 0</pose>
          <geometry>
            <mesh>
              <uri>model://arm26/meshes/visuals/arm_r_capitate.dae</uri>
              <scale>1 1 1</scale>
            </mesh>
          </geometry>
        </visual>
        <visual name='arm_r_trapezium'>
          <pose frame=''>-0 0 -0 0 -0 0</pose>
          <geometry>
            <mesh>
              <uri>model://arm26/meshes/visuals/arm_r_trapezium.dae</uri>
              <scale>1 1 1</scale>
            </mesh>
          </geometry>
        </visual>
        <visual name='arm_r_trapezoid'>
          <pose frame=''>-0 0 -0 0 -0 0</pose>
          <geometry>
            <mesh>
              <uri>model://arm26/meshes/visuals/arm_r_trapezoid.dae</uri>
              <scale>1 1 1</scale>
            </mesh>
          </geometry>
        </visual>
        <visual name='arm_r_hamate'>
          <pose frame=''>-0 0 -0 0 -0 0</pose>
          <geometry>
            <mesh>
              <uri>model://arm26/meshes/visuals/arm_r_hamate.dae</uri>
              <scale>1 1 1</scale>
            </mesh>
          </geometry>
        </visual>
        <visual name='arm_r_1mc'>
          <pose frame=''>-0 0 -0 0 -0 0</pose>
          <geometry>
            <mesh>
              <uri>model://arm26/meshes/visuals/arm_r_1mc.dae</uri>
              <scale>1 1 1</scale>
            </mesh>
          </geometry>
        </visual>
        <visual name='arm_r_2mc'>
          <pose frame=''>-0 0 -0 0 -0 0</pose>
          <geometry>
            <mesh>
              <uri>model://arm26/meshes/visuals/arm_r_2mc.dae</uri>
              <scale>1 1 1</scale>
            </mesh>
          </geometry>
        </visual>
        <visual name='arm_r_3mc'>
          <pose frame=''>-0 0 -0 0 -0 0</pose>
          <geometry>
            <mesh>
              <uri>model://arm26/meshes/visuals/arm_r_3mc.dae</uri>
              <scale>1 1 1</scale>
            </mesh>
          </geometry>
        </visual>
        <visual name='arm_r_4mc'>
          <pose frame=''>-0 0 -0 0 -0 0</pose>
          <geometry>
            <mesh>
              <uri>model://arm26/meshes/visuals/arm_r_4mc.dae</uri>
              <scale>1 1 1</scale>
            </mesh>
          </geometry>
        </visual>
        <visual name='arm_r_5mc'>
          <pose frame=''>-0 0 -0 0 -0 0</pose>
          <geometry>
            <mesh>
              <uri>model://arm26/meshes/visuals/arm_r_5mc.dae</uri>
              <scale>1 1 1</scale>
            </mesh>
          </geometry>
        </visual>
        <visual name='arm_r_thumbprox'>
          <pose frame=''>-0 0 -0 0 -0 0</pose>
          <geometry>
            <mesh>
              <uri>model://arm26/meshes/visuals/arm_r_thumbprox.dae</uri>
              <scale>1 1 1</scale>
            </mesh>
          </geometry>
        </visual>
        <visual name='arm_r_thumbdist'>
          <pose frame=''>-0 0 -0 0 -0 0</pose>
          <geometry>
            <mesh>
              <uri>model://arm26/meshes/visuals/arm_r_thumbdist.dae</uri>
              <scale>1 1 1</scale>
            </mesh>
          </geometry>
        </visual>
        <visual name='arm_r_2proxph'>
          <pose frame=''>-0 0 -0 0 -0 0</pose>
          <geometry>
            <mesh>
              <uri>model://arm26/meshes/visuals/arm_r_2proxph.dae</uri>
              <scale>1 1 1</scale>
            </mesh>
          </geometry>
        </visual>
        <visual name='arm_r_2midph'>
          <pose frame=''>-0 0 -0 0 -0 0</pose>
          <geometry>
            <mesh>
              <uri>model://arm26/meshes/visuals/arm_r_2midph.dae</uri>
              <scale>1 1 1</scale>
            </mesh>
          </geometry>
        </visual>
        <visual name='arm_r_2distph'>
          <pose frame=''>-0 0 -0 0 -0 0</pose>
          <geometry>
            <mesh>
              <uri>model://arm26/meshes/visuals/arm_r_2distph.dae</uri>
              <scale>1 1 1</scale>
            </mesh>
          </geometry>
        </visual>
        <visual name='arm_r_3proxph'>
          <pose frame=''>-0 0 -0 0 -0 0</pose>
          <geometry>
            <mesh>
              <uri>model://arm26/meshes/visuals/arm_r_3proxph.dae</uri>
              <scale>1 1 1</scale>
            </mesh>
          </geometry>
        </visual>
        <visual name='arm_r_3midph'>
          <pose frame=''>-0 0 -0 0 -0 0</pose>
          <geometry>
            <mesh>
              <uri>model://arm26/meshes/visuals/arm_r_3midph.dae</uri>
              <scale>1 1 1</scale>
            </mesh>
          </geometry>
        </visual>
        <visual name='arm_r_3distph'>
          <pose frame=''>-0 0 -0 0 -0 0</pose>
          <geometry>
            <mesh>
              <uri>model://arm26/meshes/visuals/arm_r_3distph.dae</uri>
              <scale>1 1 1</scale>
            </mesh>
          </geometry>
        </visual>
        <visual name='arm_r_4proxph'>
          <pose frame=''>-0 0 -0 0 -0 0</pose>
          <geometry>
            <mesh>
              <uri>model://arm26/meshes/visuals/arm_r_4proxph.dae</uri>
              <scale>1 1 1</scale>
            </mesh>
          </geometry>
        </visual>
        <visual name='arm_r_4midph'>
          <pose frame=''>-0 0 -0 0 -0 0</pose>
          <geometry>
            <mesh>
              <uri>model://arm26/meshes/visuals/arm_r_4midph.dae</uri>
              <scale>1 1 1</scale>
            </mesh>
          </geometry>
        </visual>
        <visual name='arm_r_4distph'>
          <pose frame=''>-0 0 -0 0 -0 0</pose>
          <geometry>
            <mesh>
              <uri>model://arm26/meshes/visuals/arm_r_4distph.dae</uri>
              <scale>1 1 1</scale>
            </mesh>
          </geometry>
        </visual>
        <visual name='arm_r_5proxph'>
          <pose frame=''>-0 0 -0 0 -0 0</pose>
          <geometry>
            <mesh>
              <uri>model://arm26/meshes/visuals/arm_r_5proxph.dae</uri>
              <scale>1 1 1</scale>
            </mesh>
          </geometry>
        </visual>
        <visual name='arm_r_5midph'>
          <pose frame=''>-0 0 -0 0 -0 0</pose>
          <geometry>
            <mesh>
              <uri>model://arm26/meshes/visuals/arm_r_5midph.dae</uri>
              <scale>1 1 1</scale>
            </mesh>
          </geometry>
        </visual>
        <visual name='arm_r_5distph'>
          <pose frame=''>-0 0 -0 0 -0 0</pose>
          <geometry>
            <mesh>
              <uri>model://arm26/meshes/visuals/arm_r_5distph.dae</uri>
              <scale>1 1 1</scale>
            </mesh>
          </geometry>
        </visual>
        <self_collide>0</self_collide>
      </link>
      <joint name='offset' type='fixed'>
        <parent>world</parent>
        <child>base</child>
      </joint>
      <joint name='r_shoulder' type='revolute'>
        <parent>base</parent>
        <child>r_humerus</child>
        <axis>
          <xyz>0 0 1</xyz>
          <dynamics>
            <damping>1e-06</damping>
            <spring_reference>0</spring_reference>
            <spring_stiffness>0</spring_stiffness>
          </dynamics>
          <limit>
            <lower>-1.5708</lower>
            <upper>3.14159</upper>
            <stiffness>100</stiffness>
            <dissipation>0.01</dissipation>
          </limit>
          <use_parent_model_frame>0</use_parent_model_frame>
        </axis>
      </joint>
      <joint name='r_elbow' type='revolute'>
        <parent>r_humerus</parent>
        <child>r_ulna_radius_hand</child>
        <axis>
          <xyz>0 0 1</xyz>
          <dynamics>
            <damping>1e-06</damping>
            <spring_reference>0</spring_reference>
            <spring_stiffness>0</spring_stiffness>
          </dynamics>
          <limit>
            <lower>0</lower>
            <upper>2.26893</upper>
            <stiffness>100</stiffness>
            <dissipation>0.01</dissipation>
          </limit>
          <use_parent_model_frame>0</use_parent_model_frame>
        </axis>
      </joint>
      <plugin name='muscle_interface_plugin' filename='libgazebo_ros_muscle_interface.so'/>
      <pose frame=''>0.007648 0.001248 0.100007 0 -0 0</pose>
    </model>
    <joint name='base_JOINT_3' type='fixed'>
      <parent>arm26::base</parent>
      <child>ExoSuitNoJoints::shoulder</child>
      <pose frame=''>0 0 0 0 -0 0</pose>
      <physics>
        <ode>
          <limit>
            <cfm>0</cfm>
            <erp>0.2</erp>
          </limit>
          <suspension>
            <cfm>0</cfm>
            <erp>0.2</erp>
          </suspension>
        </ode>
      </physics>
    </joint>
    <joint name='r_humerus_JOINT_4' type='fixed'>
      <parent>arm26::r_humerus</parent>
      <child>ExoSuitNoJoints::upperArm</child>
      <pose frame=''>0 0 0 0 -0 0</pose>
      <physics>
        <ode>
          <limit>
            <cfm>0</cfm>
            <erp>0.2</erp>
          </limit>
          <suspension>
            <cfm>0</cfm>
            <erp>0.2</erp>
          </suspension>
        </ode>
      </physics>
    </joint>
    <joint name='r_ulna_radius_hand_JOINT_5' type='fixed'>
      <parent>arm26::r_ulna_radius_hand</parent>
      <child>ExoSuitNoJoints::lowerArm</child>
      <pose frame=''>0 0 0 0 -0 0</pose>
      <physics>
        <ode>
          <limit>
            <cfm>0</cfm>
            <erp>0.2</erp>
          </limit>
          <suspension>
            <cfm>0</cfm>
            <erp>0.2</erp>
          </suspension>
        </ode>
      </physics>
    </joint>
    <static>0</static>
    <allow_auto_disable>1</allow_auto_disable>
  </model>
</sdf>
