<?xml version="1.0" ?>
<sdf version="1.6">
	<model name="ExoSuit">
		<link name="upperArm">
			<self_collide>false</self_collide>
			<pose frame="">-2.2409766979267137e-08 -0.1657005154670546 0.8534292924848815 0.0 -0.0 0.0</pose>
			<inertial>
				<pose frame="">0.0 0.0 0.0 0 0 0</pose>
				<mass>0.035365042126382314</mass>
				<inertia>
					<ixx>0.026848668803308773</ixx>
					<ixy>-1.3187678727932806e-10</ixy>
					<ixz>5.0011004972102685e-05</ixz>
					<iyy>0.025877650145656617</iyy>
					<iyz>6.783687854117204e-10</iyz>
					<izz>0.0009968080150968607</izz>
				</inertia>
			</inertial>
			<visual name="upperArm_visual">
				<geometry>
					<mesh>
						<uri>model://ExoSuit/meshes/CAD/upperArm.stl</uri>
						<scale>0.001 0.001 0.001</scale>
					</mesh>
				</geometry>
			</visual>
		</link>
		<link name="lowerArm">
			<self_collide>false</self_collide>
			<pose frame="">-5.60883944359284e-07 -0.19643676538168076 0.5886500860733177 0.0 -0.0 0.0</pose>
			<inertial>
				<pose frame="">0.0 0.0 0.0 0 0 0</pose>
				<mass>0.039028201646434786</mass>
				<inertia>
					<ixx>0.015146765092907442</ixx>
					<ixy>-4.303699452046228e-09</ixy>
					<ixz>4.495256601356099e-05</ixz>
					<iyy>0.013636010932526574</iyy>
					<iyz>1.1960276033873285e-08</iyz>
					<izz>0.0015571994124995439</izz>
				</inertia>
			</inertial>
			<visual name="lowerArm_visual">
				<geometry>
					<mesh>
						<uri>model://ExoSuit/meshes/CAD/lowerArm.stl</uri>
						<scale>0.001 0.001 0.001</scale>
					</mesh>
				</geometry>
			</visual>
		</link>
		<link name="shoulder">
			<self_collide>false</self_collide>
			<pose frame="">-7.908049805587664e-07 -0.16397633036233888 1.0812802560574826 0.0 -0.0 0.0</pose>
			<inertial>
				<pose frame="">0.0 0.0 0.0 0 0 0</pose>
				<mass>0.01630269246947046</mass>
				<inertia>
					<ixx>0.019515568502845942</ixx>
					<ixy>-1.9966507921631573e-09</ixy>
					<ixz>2.8905394265479922e-05</ixz>
					<iyy>0.019077204732443745</iyy>
					<iyz>1.3722221878786912e-08</iyz>
					<izz>0.00046497426005389167</izz>
				</inertia>
			</inertial>
			<visual name="shoulder_visual">
				<geometry>
					<mesh>
						<uri>model://ExoSuit/meshes/CAD/shoulder.stl</uri>
						<scale>0.001 0.001 0.001</scale>
					</mesh>
				</geometry>
			</visual>
		</link>
		<joint name="offset" type="fixed">
			<parent>world</parent>
			<child>shoulder</child>
		</joint>
		<joint name="shoulderJoint" type="revolute">
			<parent>shoulder</parent>
			<child>upperArm</child>
			<pose frame="">0.0 0.01 0.0 0 0 0</pose>
			<axis>
				<xyz>0.0 1.0 0.0</xyz>
				<limit>
					<lower>-3.141592653589793</lower>
					<upper>1.5707963267948966</upper>
				</limit>
				<use_parent_model_frame>0</use_parent_model_frame>
			</axis>
		</joint>
		<joint name="elbow" type="revolute">
			<parent>upperArm</parent>
			<child>lowerArm</child>
			<pose frame="">-2.064988378536746e-19 0.01 -2.0822111621573518e-20 0 0 0</pose>
			<axis>
				<xyz>-2.064988378536746e-17 1.0 -2.0822111621573517e-18</xyz>
				<limit>
					<lower>-2.2689280275926285</lower>
					<upper>0.0</upper>
				</limit>
				<use_parent_model_frame>0</use_parent_model_frame>
			</axis>
		</joint>
		<plugin filename="libgazebo_ros_muscle_interface.so" name="muscle_interface_plugin"/>
		<muscles>model://ExoSuit/muscles.osim</muscles>
	</model>
</sdf>
