<?xml version="1.0" ?>
<sdf version="1.6">
	<model name="msj_plattform">
		<link name="base">
			<self_collide>false</self_collide>
			<pose frame="">-0.00022102361284076277 0.0004833872304084981 0.029397403064397677 0.0 -0.0 0.0</pose>
			<inertial>
				<pose frame="">0.0 0.0 0.0 0 0 0</pose>
				<mass>14.613053778587425</mass>
				<inertia>
					<ixx>0.18098600987966365</ixx>
					<ixy>0.00011589315507071732</ixy>
					<ixz>-4.292455573365955e-06</ixz>
					<iyy>0.1808536603949684</iyy>
					<iyz>0.00018829481380353558</iyz>
					<izz>0.28792427126327147</izz>
				</inertia>
			</inertial>
			<visual name="base_visual">
				<geometry>
					<mesh>
						<uri>model://msj_plattform/meshes/CAD/base.stl</uri>
						<scale>0.001 0.001 0.001</scale>
					</mesh>
				</geometry>
			</visual>
		</link>
		<link name="top">
			<self_collide>false</self_collide>
			<pose frame="">0.04305354710017472 0.08311787866235307 0.14788815817748618 0.0 -0.0 0.0</pose>
			<inertial>
				<pose frame="">0.0 0.0 0.0 0 0 0</pose>
				<mass>1.1238336521816616</mass>
				<inertia>
					<ixx>0.03330450791256844</ixx>
					<ixy>-0.0039708493908726565</ixy>
					<ixz>-0.00013766829057208532</ixz>
					<iyy>0.027687832754021736</iyy>
					<iyz>-0.007125622342949349</iyz>
					<izz>0.010821066894400514</izz>
				</inertia>
			</inertial>
			<visual name="top_visual">
				<geometry>
					<mesh>
						<uri>model://msj_plattform/meshes/CAD/top.stl</uri>
						<scale>0.001 0.001 0.001</scale>
					</mesh>
				</geometry>
			</visual>
		</link>
		<link name="sphere_link1">
			<self_collide>false</self_collide>
			<pose frame="">0.0011058462979125978 0.0022873042555783285 0.10167501675301774 0.0 -0.0 0.0</pose>
			<inertial>
				<pose frame="">0.0 0.0 0.0 0 0 0</pose>
				<mass>0.06979038576289653</mass>
				<inertia>
					<ixx>0.0007334920838378818</ixx>
					<ixy>-1.7652886803334748e-07</ixy>
					<ixz>-1.623057065214731e-07</ixz>
					<iyy>0.0007332123043055093</iyy>
					<iyz>-7.847017477074861e-06</iyz>
					<izz>1.2097749947233721e-05</izz>
				</inertia>
			</inertial>
			<visual name="sphere_link1_visual">
				<geometry>
					<mesh>
						<uri>model://msj_plattform/meshes/CAD/sphere_link1.stl</uri>
						<scale>0.001 0.001 0.001</scale>
					</mesh>
				</geometry>
			</visual>
		</link>
		<link name="sphere_link2">
			<self_collide>false</self_collide>
			<pose frame="">0.0011058464306515797 0.00228730407265211 0.10167501675338195 0.0 -0.0 0.0</pose>
			<inertial>
				<pose frame="">0.0 0.0 0.0 0 0 0</pose>
				<mass>0.0467825615906554</mass>
				<inertia>
					<ixx>0.0004891353761314257</ixx>
					<ixy>-1.1833237471686721e-07</ixy>
					<ixz>-1.0879831113778617e-07</ixz>
					<iyy>0.0004889478314849234</iyy>
					<iyz>-5.260088742560535e-06</iyz>
					<izz>5.563398607573075e-06</izz>
				</inertia>
			</inertial>
			<visual name="sphere_link2_visual">
				<geometry>
					<mesh>
						<uri>model://msj_plattform/meshes/CAD/sphere_link2.stl</uri>
						<scale>0.001 0.001 0.001</scale>
					</mesh>
				</geometry>
			</visual>
		</link>
		<joint name="sphere_axis0" type="revolute">
			<parent>base</parent>
			<child>sphere_link1</child>
			<pose frame="">4.687507854095329e-10 -5.820251680610511e-10 2.58236099170972e-12 0 0 0</pose>
			<axis>
				<xyz>0.7116922180791252 0.030634651659215216 -0.7018231293163064</xyz>
				<limit>
					<lower>-3.141592653589793</lower>
					<upper>3.141592653589793</upper>
				</limit>
				<use_parent_model_frame>0</use_parent_model_frame>
			</axis>
		</joint>
		<joint name="sphere_axis2" type="revolute">
			<parent>sphere_link2</parent>
			<child>top</child>
			<pose frame="">-0.041947700333511265 -0.08083057498879992 -0.046213141421886234 0 0 0</pose>
			<axis>
				<xyz>0.41232849962294216 0.7906352177898321 0.4526380019277172</xyz>
				<limit>
					<lower>-3.141592653589793</lower>
					<upper>3.141592653589793</upper>
				</limit>
				<use_parent_model_frame>0</use_parent_model_frame>
			</axis>
		</joint>
		<joint name="sphere_axis1" type="revolute">
			<parent>sphere_link1</parent>
			<child>sphere_link2</child>
			<pose frame="">3.3601183904719003e-10 -3.9909894500311796e-10 2.217959149675153e-12 0 0 0</pose>
			<axis>
				<xyz>0.5687524902137173 -0.6115206214905139 0.5500573918852061</xyz>
				<limit>
					<lower>-3.141592653589793</lower>
					<upper>3.141592653589793</upper>
				</limit>
				<use_parent_model_frame>0</use_parent_model_frame>
			</axis>
		</joint>
		<plugin filename="libgazebo_ros_muscle_interface.so" name="muscle_interface_plugin"/>
		<muscles>model://msj_plattform/muscles.osim</muscles>
	</model>
</sdf>
