<?xml version="1.0" ?>
<sdf version="1.5">
  <model name="leg6dof9musc">
    <muscles>model://leg6dof9musc/muscles.osim</muscles>
    <link name="pelvis">
      <pose frame="">0.593075 -0.017089 0.0 1.5708 0.0 0.0</pose>
      <inertial>
        <mass>10.75379227</mass>
        <pose>0.0 0.0 0.0 0.0 0.0 0.0</pose>
        <inertia>
          <ixx>0.1027003</ixx>
          <ixy>0</ixy>
          <ixz>0</ixz>
          <iyy>0.08701554</iyy>
          <iyz>0</iyz>
          <izz>0.05784385</izz>
        </inertia>
      </inertial>
      <visual name="sacrum">
        <pose> -0 0 -0 0 0 0</pose>
        <geometry>
          <mesh>
            <uri>model://leg6dof9musc/meshes/visuals/sacrum.dae</uri>
            <scale> 1 1 1</scale>
          </mesh>
        </geometry>
      </visual>
      <visual name="pelvis">
        <pose> -0 0 -0 0 0 0</pose>
        <geometry>
          <mesh>
            <uri>model://leg6dof9musc/meshes/visuals/pelvis.dae</uri>
            <scale> 1 1 1</scale>
          </mesh>
        </geometry>
      </visual>
      <visual name="l_pelvis">
        <pose> -0 0 -0 0 0 0</pose>
        <geometry>
          <mesh>
            <uri>model://leg6dof9musc/meshes/visuals/l_pelvis.dae</uri>
            <scale> 1 1 1</scale>
          </mesh>
        </geometry>
      </visual>
    </link>
    <link name="femur_r">
      <pose frame="">0.5191238 -0.1044288 -0.0691397 1.5708 0.0 0.0</pose>
      <inertial>
        <mass>8.54926632</mass>
        <pose>0.0 0.0 0.0 0.0 0.0 0.0</pose>
        <inertia>
          <ixx>0.16956431</ixx>
          <ixy>0</ixy>
          <ixz>0</ixz>
          <iyy>0.0444489</iyy>
          <iyz>0</iyz>
          <izz>0.17880867</izz>
        </inertia>
      </inertial>
      <visual name="femur_r">
        <pose> -0 0 -0 0 0 0</pose>
        <geometry>
          <mesh>
            <uri>model://leg6dof9musc/meshes/visuals/femur_r.dae</uri>
            <scale> 1 1 1</scale>
          </mesh>
        </geometry>
      </visual>
    </link>
    <link name="tibia_r">
      <pose frame="">0.5191238 -0.1044288 -0.0691397 1.5708 0.0 0.0</pose>
      <inertial>
        <mass>4.67404243</mass>
        <pose>0.0 0.0 0.0 0.0 0.0 0.0</pose>
        <inertia>
          <ixx>0.08023514</ixx>
          <ixy>0</ixy>
          <ixz>0</ixz>
          <iyy>0.00811903</iyy>
          <iyz>0</iyz>
          <izz>0.08134951</izz>
        </inertia>
      </inertial>
      <visual name="tibia_r">
        <pose> -0 0 -0 0 0 0</pose>
        <geometry>
          <mesh>
            <uri>model://leg6dof9musc/meshes/visuals/tibia_r.dae</uri>
            <scale> 1 1 1</scale>
          </mesh>
        </geometry>
      </visual>
      <visual name="fibula_r">
        <pose> -0 0 -0 0 0 0</pose>
        <geometry>
          <mesh>
            <uri>model://leg6dof9musc/meshes/visuals/fibula_r.dae</uri>
            <scale> 1 1 1</scale>
          </mesh>
        </geometry>
      </visual>
    </link>
    <link name="patella_r">
      <pose frame="">0.5191238 -0.1044288 -0.0691397 1.5708 0.0 0.0</pose>
      <inertial>
        <mass>0.09191376</mass>
        <pose>0.0 0.0 0.0 0.0 0.0 0.0</pose>
        <inertia>
          <ixx>0.00110296</ixx>
          <ixy>0</ixy>
          <ixz>0</ixz>
          <iyy>0.00110296</iyy>
          <iyz>0</iyz>
          <izz>0.00110296</izz>
        </inertia>
      </inertial>
      <visual name="pat">
        <pose> -0 0 -0 0 0 0</pose>
        <geometry>
          <mesh>
            <uri>model://leg6dof9musc/meshes/visuals/pat.dae</uri>
            <scale> 1 1 1</scale>
          </mesh>
        </geometry>
      </visual>
    </link>
    <link name="talus_r">
      <pose frame="">0.5191238 -0.1044288 -0.5523427 1.5708 0.0 0.0</pose>
      <inertial>
        <mass>0.12606858</mass>
        <pose>0.0 0.0 0.0 0.0 0.0 0.0</pose>
        <inertia>
          <ixx>0.00202166</ixx>
          <ixy>0</ixy>
          <ixz>0</ixz>
          <iyy>0.00202166</iyy>
          <iyz>0</iyz>
          <izz>0.00202166</izz>
        </inertia>
      </inertial>
      <visual name="talus">
        <pose> -0 0 -0 0 0 0</pose>
        <geometry>
          <mesh>
            <uri>model://leg6dof9musc/meshes/visuals/talus.dae</uri>
            <scale> 1 1 1</scale>
          </mesh>
        </geometry>
      </visual>
    </link>
    <link name="calcn_r">
      <pose frame="">0.457073 -0.1145595 -0.6055291 1.5708 0.0 0.0</pose>
      <inertial>
        <mass>1.07224816</mass>
        <pose>0.0 0.0 0.0 0.0 0.0 0.0</pose>
        <inertia>
          <ixx>0.00090462</ixx>
          <ixy>0</ixy>
          <ixz>0</ixz>
          <iyy>0.00361848</iyy>
          <iyz>0</iyz>
          <izz>0.00361848</izz>
        </inertia>
      </inertial>
      <visual name="foot">
        <pose> -0 0 -0 0 0 0</pose>
        <geometry>
          <mesh>
            <uri>model://leg6dof9musc/meshes/visuals/foot.dae</uri>
            <scale> 1 1 1</scale>
          </mesh>
        </geometry>
      </visual>
    </link>
    <link name="toes_r">
      <pose frame="">0.640893 -0.11558642 -0.60758296 1.5708 0.0 0.0</pose>
      <inertial>
        <mass>0.18614228</mass>
        <pose>0.0 0.0 0.0 0.0 0.0 0.0</pose>
        <inertia>
          <ixx>0</ixx>
          <ixy>0</ixy>
          <ixz>0</ixz>
          <iyy>0</iyy>
          <iyz>0</iyz>
          <izz>0.00090462</izz>
        </inertia>
      </inertial>
      <visual name="bofoot">
        <pose> -0 0 -0 0 0 0</pose>
        <geometry>
          <mesh>
            <uri>model://leg6dof9musc/meshes/visuals/bofoot.dae</uri>
            <scale> 1 1 1</scale>
          </mesh>
        </geometry>
      </visual>
    </link>
    <joint name="ground_pelvis" type="ball">
      <parent>ground</parent>
      <child>pelvis</child>
    </joint>
    <joint name="hip_r" type="ball">
      <parent>pelvis</parent>
      <child>femur_r</child>
    </joint>
    <joint name="knee_r" type="ball">
      <parent>femur_r</parent>
      <child>tibia_r</child>
    </joint>
    <joint name="tib_pat_r" type="ball">
      <parent>tibia_r</parent>
      <child>patella_r</child>
    </joint>
    <joint name="ankle_r" type="ball">
      <parent>tibia_r</parent>
      <child>talus_r</child>
    </joint>
    <joint name="subtalar_r" type="fixed">
      <parent>talus_r</parent>
      <child>calcn_r</child>
    </joint>
    <joint name="mtp_r" type="fixed">
      <parent>calcn_r</parent>
      <child>toes_r</child>
    </joint>
    <plugin filename="libgazebo_ros_muscle_interface.so" name="muscle_interface_plugin"/>
  </model>
</sdf>
